Workbook
Name adiposo: 'HOJA DE TRABAJO'!#REF!
Name adiposo_muscular: 'HOJA DE TRABAJO'!#REF!
Name AF: 'HOJA DE TRABAJO'!#REF!
Name arq: '[1]Proc datos brutos'!$AH$3:$AJ$48
Name defcen: '[1]Proc datos brutos'!$AK$3:$AM$48
Name deflat: '[1]Proc datos brutos'!$AN$3:$AP$48
Name delcen: '[1]Proc datos brutos'!$AZ$3:$BB$48
Name dellat: '[1]Proc datos brutos'!$AW$3:$AY$48
Name depf: 'HOJA DE TRABAJO'!#REF!
Name depm: 'HOJA DE TRABAJO'!#REF!
Name deps: 'HOJA DE TRABAJO'!#REF!
Name meddef: '[1]Proc datos brutos'!$AQ$3:$AS$48
Name medof: '[1]Proc datos brutos'!$AT$3:$AV$48
Name muscular: 'HOJA DE TRABAJO'!#REF!
Name muscular_osea: 'HOJA DE TRABAJO'!#REF!
Name posiciones: '[1]Proc datos brutos'!$BD$2:$BF$8

Sheet HOJA DE TRABAJO
A2: Nombre: | G2: Sexo (m=1;f=2):
A3: Fecha: | C3: Fecha de Nac. | G3: Edad decimal: | I3: =(B3-E3)/365.25 -> 0
A4: Variable | B4: serie 1 | C4: serie 2 | D4: serie 3 | E4: serie 4 | F4: serie 5 | G4: mediana
A5: DATOS BÁSICOS
A6: Peso Bruto (Kg) | G6: =ROUND(MEDIAN(B6:F6),3) -> #NUM!
A7: Talla Corporal (cm) | G7: =ROUND(MEDIAN(B7:F7),3) -> #NUM!
A8: DIÁMETROS (cm)
A9: Humeral (biepicondilar) | G9: =ROUND(MEDIAN(B9:F9),3) -> #NUM!
A10: Femoral (biepicondilar) | G10: =ROUND(MEDIAN(B10:F10),3) -> #NUM!
A11: PERÍMETROS (cm)
A12: Brazo Relajado | G12: =ROUND(MEDIAN(B12:F12),3) -> #NUM!
A13: Brazo Flexionado en Tensión | G13: =ROUND(MEDIAN(B13:F13),3) -> #NUM!
A14: Cintura (mínima) | G14: =ROUND(MEDIAN(B14:F14),3) -> #NUM!
A15: Cadera (máximo) | G15: =ROUND(MEDIAN(B15:F15),3) -> #NUM!
A16: Pantorrilla (máxima) | G16: =ROUND(MEDIAN(B16:F16),3) -> #NUM!
A17: PLIEGUES CUTÁNEOS (mm)
A18: Tríceps | G18: =ROUND(MEDIAN(B18:F18),3) -> #NUM!
A19: Subescapular | G19: =ROUND(MEDIAN(B19:F19),3) -> #NUM!
A20: Bíceps | G20: =ROUND(MEDIAN(B20:F20),3) -> #NUM!
A21: Cresta ilíaca | G21: =ROUND(MEDIAN(B21:F21),3) -> #NUM!
A22: Supraespinal | G22: =ROUND(MEDIAN(B22:F22),3) -> #NUM!
A23: Abdominal | G23: =ROUND(MEDIAN(B23:F23),3) -> #NUM!
A24: Muslo Medial | G24: =ROUND(MEDIAN(B24:F24),3) -> #NUM!
A25: Pantorrilla (máxima) | G25: =ROUND(MEDIAN(B25:F25),3) -> #NUM!
A27: NO IMPRIMIR ESTA HOJA
A28: Somatotipo de Heath & Carter (1990)
A30: Endomorphy | B30: =(-0.7182+(0.1451*B31)-(0.00068*B31^2)+(0.0000014*B31^3)) -> #NUM!
A31: Sum SF | B31: =SUM(G18+G22+G19)*170.18/$G$7 -> #NUM!
A33: Mesomorphy | B33: =(0.858*G9)+(0.601*G10)+(0.188*(G13-G18/10))+(0.161*(G16-G25/10))-(G7*0.131)+4.5 -> #NUM!
A35: Ectomorphy | B35: =IF(B36>=40.75,0.732*B36-28.58,0.463*B36-17.63) -> #NUM!
A36: HWR | B36: =G7/(G6)^0.3333 -> #NUM!
A38: comp corporal | C38: densidad
A39: D&W | C39: masc | D39: fem
A40: suma 4p | B40: =B18+B19+B20+B21 -> 0
A41: log suma 4p | B41: =LOG(B40) -> #NUM! | C41: =1.1765-(0.0744*B41) -> #NUM! | D41: =1.1567-(0.0717*B41) -> #NUM!
A42: %graso Durnin | C42: =(495/C41)-450 -> #NUM! | D42: =(495/D41)-450 -> #NUM!
A43: Withers 1987
A44: suma 7 p MASC | B44: =G18+G19+G20+G22+G23+G24+G25 -> #NUM! | C44: =1.0988-(0.0004*(B44)) -> #NUM! | D44: =1.17484-(0.07229*LOG(B45)) -> #NUM!
A45: SUMA 4P FEM | B45: =G18+G19+G22+G25 -> #NUM!
A46: %graso Withers | C46: =(495/C44)-450 -> #NUM! | D46: =(495/D44)-450 -> #NUM!
...

Sheet INFORME IMPRIMIR
A1: Informe de Composición Corporal Nivel 1 | I1: Francis Holway NUTRICION DEPORTIVA Teléfono: 4822-9436 E-mail: fholway@hotmail.com
C3: Nombre: | D3: ='HOJA DE TRABAJO'!B2 -> 0 | H3: Edad: | I3: ='HOJA DE TRABAJO'!I3 -> 0
F5: Fecha de medición: | H5: ='HOJA DE TRABAJO'!B3 -> 0
E8: Resultados | F8: Valor Ajustado | L8: EJES
B10: Peso (kg) | E10: ='HOJA DE TRABAJO'!G6 -> #NUM! | L10: 3 | M10: 2
B11: Talla (cm) | E11: ='HOJA DE TRABAJO'!G7 -> #NUM!
B12: Humeral (biepicondilar) | E12: ='HOJA DE TRABAJO'!G9 -> #NUM! | L12: 2 | M12: 1
B13: Femoral (biepicondilar) | E13: ='HOJA DE TRABAJO'!G10 -> #NUM!
B14: Brazo Relajado | E14: ='HOJA DE TRABAJO'!G12 -> #NUM! | M14: 6
B15: Brazo Flexionado en Tensión | E15: ='HOJA DE TRABAJO'!G13 -> #NUM! | M15: 5
B16: Cintura (mínima) | E16: ='HOJA DE TRABAJO'!G14 -> #NUM! | M16: 4
B17: Caderas (máxima) | E17: ='HOJA DE TRABAJO'!G15 -> #NUM! | M17: 3
B18: Pantorrilla (máxima) | E18: ='HOJA DE TRABAJO'!G16 -> #NUM! | M18: 2
B19: Tríceps | E19: ='HOJA DE TRABAJO'!G18 -> #NUM! | M19: 1
B20: Subescapular | E20: ='HOJA DE TRABAJO'!G19 -> #NUM!
B21: Bíceps | E21: ='HOJA DE TRABAJO'!G20 -> #NUM! | M21: 10
B22: Cresta Ilíaca | E22: ='HOJA DE TRABAJO'!G21 -> #NUM! | M22: 9
B23: Supraespinal | E23: ='HOJA DE TRABAJO'!G22 -> #NUM! | M23: 8
B24: Abdominal | E24: ='HOJA DE TRABAJO'!G23 -> #NUM! | L24: 9 | M24: 7
B25: Muslo (medial) | E25: ='HOJA DE TRABAJO'!G24 -> #NUM! | L25: 8 | M25: 6
B26: Pantorrilla | E26: ='HOJA DE TRABAJO'!G25 -> #NUM! | L26: 7 | M26: 5
M27: 6
B28: Índices y composición corporal (Durnin & Womersley y Withers)
B29: IMC | C29: kg/m-2 | E29: =E10/(E11*0.01)^2 -> #NUM! | L29: 14 | M29: 5
B30: IndCint/Cad | E30: =E16/E17 -> #NUM!
B31: Suma 6 pl | C31: mm | E31: =E19+E20+E23+E24+E25+E26 -> #NUM!
B32: % graso | C32: Durnin & W | E32: =IF('HOJA DE TRABAJO'!I2=1,+'HOJA DE TRABAJO'!C42,+'HOJA DE TRABAJO'!D42) -> #NUM! | G32: Indices T^2 | M32: 4
B33: Grasa | C33: kg | E33: =E10*E32/100 -> #NUM! | F33: Fat Mass Index | I33: =E33/(E11/100)^2 -> #NUM! | J33: Kg*m-2 | L33: 12 | M33: 3
B34: Magra | C34: kg | E34: =E10-E33 -> #NUM! | F34: Fat-Free Mass Index | I34: =E34/(E11/100)^2 -> #NUM! | J34: Kg*m-2 | L34: 10 | M34: 2
M35: 1
B36: % graso | C36: Withers (atletas) | E36: =IF('HOJA DE TRABAJO'!I2=1,+'HOJA DE TRABAJO'!C46,+'HOJA DE TRABAJO'!D46) -> #NUM! | L36: 7
B37: Grasa | C37: kg | E37: =E10*E36/100 -> #NUM! | F37: Fat Mass Index | I37: =E37/(E11/100)^2 -> #NUM! | J37: Kg*m-2 | L37: 6
B38: Magra | C38: kg | E38: =E10-E37 -> #NUM! | F38: Fat-Free Mass Index | I38: =E38/(E11/100)^2 -> #NUM! | J38: Kg*m-2 | L38: 5
L39: 4
B40: Area Musc Brazo mm2 | E40: ='HOJA DE TRABAJO'!B48 -> 0 | L40: 3
L41: 2
A44: Somatotipo de Heath & Carter (1990) | I44: Francis Holway NUTRICION DEPORTIVA Teléfono: 4822-9436 E-mail: fholway@hotmail.com
C46: Nombre: | D46: ='HOJA DE TRABAJO'!B2 -> 0 | H46: Edad: | I46: ='HOJA DE TRABAJO'!I3 -> 0
C48: Número de medición: | E48: ='HOJA DE TRABAJO'!I1 -> 0 | F48: Fecha de medición: | H48: ='HOJA DE TRABAJO'!B3 -> 0
A50: Sumatoria de pliegues: | C50: =SUM(E19,E20,E23) -> #NUM! | D50: per.correg. brazo: | F50: =E15-E19/10 -> #NUM! | G50: raíz cúbica del peso: | I50: =E10^0.33333 -> #NUM!
...

Sheet CALCULO PESO IDEAL
F1: Objetivo % graso | G1: Peso y composición ideal | H1: Cantidad de grasa a bajar Kg | I1: Indices talla^2 | J1: Objetivo FFMI Kg/m-2 | K1: Cantidad de masa magra a subir Kg
B2: Peso | C2: Kg | E2: ='INFORME IMPRIMIR'!E10 -> #NUM! | G2: =(E5*100/(100-F3)) -> #NUM!
B3: % graso | C3: Durnin & W | E3: ='INFORME IMPRIMIR'!E32 -> #NUM!
B4: Grasa | C4: kg | E4: ='INFORME IMPRIMIR'!E33 -> #NUM! | G4: =G2*F3*0.01 -> #NUM! | H4: =+E4-G4 -> #NUM! | I4: =E4/(C13)^2 -> #NUM!
B5: Magra | C5: kg | E5: ='INFORME IMPRIMIR'!E34 -> #NUM! | G5: =E5 -> #NUM! | I5: =E5/C13^2 -> #NUM! | J5: =C13^2*J3 -> #NUM! | K5: =J5-G5 -> #NUM!
B7: Peso | C7: Kg | E7: ='INFORME IMPRIMIR'!E10 -> #NUM! | G7: =(E10*100/(100-F8)) -> #NUM!
B8: % graso | C8: Withers (atletas) | E8: ='INFORME IMPRIMIR'!E36 -> #NUM!
B9: Grasa | C9: kg | E9: ='INFORME IMPRIMIR'!E37 -> #NUM! | G9: =G7*F8*0.01 -> #NUM! | H9: =+E9-G9 -> #NUM! | I9: =E9/(C13)^2 -> #NUM!
B10: Magra | C10: kg | E10: ='INFORME IMPRIMIR'!E38 -> #NUM! | G10: =E10 -> #NUM! | I10: =E10/C13^2 -> #NUM! | J10: =J7*C13^2 -> #NUM! | K10: =J10-G10 -> #NUM!
B12: Estatura cm | C12: ='HOJA DE TRABAJO'!G7 -> #NUM!
B13: Estatura m | C13: =C12/100 -> #NUM!

Sheet REFERENCIAS
C2: CATEGORIAS DE %GRASO E INDICES T^2
K3: FFMI
K4: límite superior natural masculino: 24,0 á 25,0 Kg*m-2
K5: límite superior natural femenino: 19,0 á 20,0 Kg*m-2
B38: AREA MUSCULAR BRAZO
